<?xml version="1.0" encoding="utf-8"?>
<!-- This URDF was automatically created by SolidWorks to URDF Exporter! Originally created by Stephen Brawner (brawner@gmail.com) 
     Commit Version: 1.6.0-4-g7f85cfe  Build Version: 1.6.7995.38578
     For more information, please see http://wiki.ros.org/sw_urdf_exporter -->
<robot xmlns:xacro="http://www.ros.org/wiki/xacro">
  <link
    name="base_link">
    <inertial>
      <origin
        xyz="-0.16872 0.029095 0.38393"
        rpy="0 0 0" />
      <mass
        value="0.50183" />
      <inertia
        ixx="0.0012683"
        ixy="6.1204E-06"
        ixz="-1.9722E-05"
        iyy="0.001121"
        iyz="-0.00013289"
        izz="0.00040527" />
    </inertial>
    <visual>
      <origin
        xyz="0 0 0"
        rpy="0 0 0" />
      <geometry>
        <mesh
          filename="package://bearmax_description/meshes/base_link.STL" />
      </geometry>
      <material
        name="">
        <color
          rgba="0.79216 0.81961 0.93333 1" />
      </material>
    </visual>
    <collision>
      <origin
        xyz="0 0 0"
        rpy="0 0 0" />
      <geometry>
        <mesh
          filename="package://bearmax_description/meshes/base_link.STL" />
      </geometry>
    </collision>
  </link>
  <link
    name="chassis_link">
    <inertial>
      <origin
        xyz="2.05243877449135E-09 0.199756451230963 9.88551460134879E-09"
          rpy="0 0 0" />
      <mass
        value="0.057634280998379" />
      <inertia
        ixx="0.00076957046688273"
        ixy="-5.57335799211552E-12"
        ixz="2.35298455540754E-12"
        iyy="7.67989249701802E-06"
        iyz="-6.85667104359074E-11"
        izz="0.000769592745255331" />
    </inertial>
    <visual>
      <origin
        xyz="0 0 0"
        rpy="0 0 0" />
      <geometry>
        <mesh
          filename="package://bearmax_description/meshes/chassis_link.STL" />
      </geometry>
      <material
        name="">
        <color
          rgba="0.792156862745098 0.819607843137255 0.933333333333333 1" />
      </material>
    </visual>
    <collision>
      <origin
        xyz="0 0 0"
        rpy="0 0 0" />
      <geometry>
        <mesh
          filename="package://bearmax_description/meshes/chassis_link.STL" />
      </geometry>
    </collision>
  </link>
  <joint
    name="chassis_joint"
    type="continuous">
    <origin
      xyz="-0.17647 -0.39012 0.00039009"
      rpy="1.5708 0.17453 1.5708" />
    <parent
      link="base_link" />
    <child
      link="chassis_link" />
    <axis
      xyz="0 1 0" />
  </joint>
  <link
    name="torso_link">
    <inertial>
      <origin
        xyz="-0.0328112235007646 0.0261239783443282 -0.0433673919898587"
          rpy="${pi} 0 0" />
      <mass
        value="2.66972928885767" />
      <inertia
        ixx="0.00404110287002202"
        ixy="-1.01198618234364E-08"
        ixz="1.34106253652217E-07"
        iyy="0.00697222700032066"
        iyz="-2.67463094444495E-08"
        izz="0.00371306709074572" />
    </inertial>
    <visual>
      <origin
        xyz="0 0 0"
        rpy="${pi} 0 0" />
      <geometry>
        <mesh
          filename="package://bearmax_description/meshes/torso_link.STL" />
      </geometry>
      <material
        name="">
        <color
          rgba="0.792156862745098 0.819607843137255 0.933333333333333 1" />
      </material>
    </visual>
    <collision>
      <origin
        xyz="0 0 0"
        rpy="${pi} 0 0" />
      <geometry>
        <mesh
          filename="package://bearmax_description/meshes/torso_link.STL" />
      </geometry>
    </collision>
  </link>
  <joint
    name="torso_joint"
    type="fixed">
    <origin
      xyz="0 0.4005 0"
      rpy="3.1416 -1.5708 0" />
    <parent
      link="chassis_link" />
    <child
      link="torso_link" />
    <axis
      xyz="0 0 0" />
  </joint>
  <link
    name="left_arm_shoulder_link">
    <inertial>
      <origin
        xyz="-0.00128474063714754 0.0372806590016448 0.000725481006650985"
        rpy="0 0 0" />
      <mass
        value="0.0906427985508071" />
      <inertia
        ixx="1.86582808083285E-05"
        ixy="-7.27809404404332E-08"
        ixz="-2.23950447127529E-06"
        iyy="3.12235840145014E-05"
        iyz="-4.23232409502064E-07"
        izz="2.20214130274902E-05" />
    </inertial>
    <visual>
      <origin
        xyz="0 0 0"
        rpy="0 0 0" />
      <geometry>
        <mesh
          filename="package://bearmax_description/meshes/left_arm_shoulder_link.STL" />
      </geometry>
      <material
        name="">
        <color
          rgba="0.792156862745098 0.819607843137255 0.933333333333333 1" />
      </material>
    </visual>
    <collision>
      <origin
        xyz="0 0 0"
        rpy="0 0 0" />
      <geometry>
        <mesh
          filename="package://bearmax_description/meshes/left_arm_shoulder_link.STL" />
      </geometry>
    </collision>
  </link>
  <joint
    name="left_arm_shoulder_joint"
    type="continuous">
    <origin
      xyz="0.1157 0.02246 -0.010325"
      rpy="-3.1416 1.1281 1.7453" />
    <parent
      link="torso_link" />
    <child
      link="left_arm_shoulder_link" />
    <axis
      xyz="0 1 0" />
  </joint>
  <link
    name="left_arm_rotator_link">
    <inertial>
      <origin
        xyz="-0.00821004209420206 0.077156918575758 -0.00821004209420223"
        rpy="0 0 0" />
      <mass
        value="0.0559746633437899" />
      <inertia
        ixx="7.24711865259699E-05"
        ixy="2.89533753363413E-06"
        ixz="9.00615014902878E-07"
        iyy="6.85800622969301E-06"
        iyz="2.89533753363435E-06"
        izz="7.24711865259698E-05" />
    </inertial>
    <visual>
      <origin
        xyz="0 0 0"
        rpy="0 0 0" />
      <geometry>
        <mesh
          filename="package://bearmax_description/meshes/left_arm_rotator_link.STL" />
      </geometry>
      <material
        name="">
        <color
          rgba="0.792156862745098 0.819607843137255 0.933333333333333 1" />
      </material>
    </visual>
    <collision>
      <origin
        xyz="0 0 0"
        rpy="0 0 0" />
      <geometry>
        <mesh
          filename="package://bearmax_description/meshes/left_arm_rotator_link.STL" />
      </geometry>
    </collision>
  </link>
  <joint
    name="left_arm_rotator_joint"
    type="continuous">
    <origin
      xyz="-0.022117 0.0497 0.014308"
      rpy="2.0286 -0.26374 -1.0841" />
    <parent
      link="left_arm_shoulder_link" />
    <child
      link="left_arm_rotator_link" />
    <axis
      xyz="0 1 0" />
  </joint>
  <link
    name="left_arm_elbow_link">
    <inertial>
      <origin
        xyz="0.0405860587058995 0.00726331258179899 2.22044604925031E-16"
        rpy="0 0 0" />
      <mass
        value="0.0356564342065887" />
      <inertia
        ixx="2.91755755317522E-06"
        ixy="5.70063169884467E-08"
        ixz="-1.02596865736177E-19"
        iyy="4.3073139448888E-05"
        iyz="2.5410988417629E-21"
        izz="4.0731009181031E-05" />
    </inertial>
    <visual>
      <origin
        xyz="0 0 0"
        rpy="0 0 0" />
      <geometry>
        <mesh
          filename="package://bearmax_description/meshes/left_arm_elbow_link.STL" />
      </geometry>
      <material
        name="">
        <color
          rgba="0.792156862745098 0.819607843137255 0.933333333333333 1" />
      </material>
    </visual>
    <collision>
      <origin
        xyz="0 0 0"
        rpy="0 0 0" />
      <geometry>
        <mesh
          filename="package://bearmax_description/meshes/left_arm_elbow_link.STL" />
      </geometry>
    </collision>
  </link>
  <joint
    name="left_arm_elbow_joint"
    type="continuous">
    <origin
      xyz="0.0018031 0.1211 0.0018031"
      rpy="2.2751 -0.38212 1.9844" />
    <parent
      link="left_arm_rotator_link" />
    <child
      link="left_arm_elbow_link" />
    <axis
      xyz="0 1 0" />
  </joint>
  <link
    name="right_arm_shoulder_link">
    <inertial>
      <origin
        xyz="0.00128474063714612 0.0188602418328267 0.000725481006649376"
        rpy="0 0 0" />
      <mass
        value="0.0906427985508071" />
      <inertia
        ixx="1.86582808083285E-05"
        ixy="7.27809404404447E-08"
        ixz="2.2395044712753E-06"
        iyy="3.12235840145013E-05"
        iyz="-4.23232409502124E-07"
        izz="2.20214130274902E-05" />
    </inertial>
    <visual>
      <origin
        xyz="0 0 0"
        rpy="0 0 0" />
      <geometry>
        <mesh
          filename="package://bearmax_description/meshes/right_arm_shoulder_link.STL" />
      </geometry>
      <material
        name="">
        <color
          rgba="0.792156862745098 0.819607843137255 0.933333333333333 1" />
      </material>
    </visual>
    <collision>
      <origin
        xyz="0 0 0"
        rpy="0 0 0" />
      <geometry>
        <mesh
          filename="package://bearmax_description/meshes/right_arm_shoulder_link.STL" />
      </geometry>
    </collision>
  </link>
  <joint
    name="right_arm_shoulder_joint"
    type="continuous">
    <origin
      xyz="-0.14465 0.027768 -0.0102"
      rpy="-3.1416 -1.0813 -1.7453" />
    <parent
      link="torso_link" />
    <child
      link="right_arm_shoulder_link" />
    <axis
      xyz="0 1 0" />
  </joint>
  <link
    name="right_arm_rotator_link">
    <inertial>
      <origin
        xyz="-0.00821004209420215 0.0772962147120626 -0.00821004209420206"
        rpy="0 0 0" />
      <mass
        value="0.0559746633437899" />
      <inertia
        ixx="7.247118652597E-05"
        ixy="2.83145992905549E-06"
        ixz="9.00615014902898E-07"
        iyy="6.85800622969301E-06"
        iyz="2.83145992905536E-06"
        izz="7.247118652597E-05" />
    </inertial>
    <visual>
      <origin
        xyz="0 0 0"
        rpy="0 0 0" />
      <geometry>
        <mesh
          filename="package://bearmax_description/meshes/right_arm_rotator_link.STL" />
      </geometry>
      <material
        name="">
        <color
          rgba="0.792156862745098 0.819607843137255 0.933333333333333 1" />
      </material>
    </visual>
    <collision>
      <origin
        xyz="0 0 0"
        rpy="0 0 0" />
      <geometry>
        <mesh
          filename="package://bearmax_description/meshes/right_arm_rotator_link.STL" />
      </geometry>
    </collision>
  </link>
  <joint
    name="right_arm_rotator_joint"
    type="continuous">
    <origin
      xyz="0.022117 0.020269 0.014308"
      rpy="1.1565 0.3299 -0.93593" />
    <parent
      link="right_arm_shoulder_link" />
    <child
      link="right_arm_rotator_link" />
    <axis
      xyz="0 1 0" />
  </joint>
  <link
    name="right_arm_elbow_link">
    <inertial>
      <origin
        xyz="0.0405860587058996 0.00726331258179902 1.11022302462516E-16"
        rpy="0 0 0" />
      <mass
        value="0.0356564342065887" />
      <inertia
        ixx="2.91755755317521E-06"
        ixy="5.70063169883899E-08"
        ixz="2.85873619698326E-20"
        iyy="4.3073139448888E-05"
        iyz="1.21760986167806E-21"
        izz="4.0731009181031E-05" />
    </inertial>
    <visual>
      <origin
        xyz="0 0 0"
        rpy="0 0 0" />
      <geometry>
        <mesh
          filename="package://bearmax_description/meshes/right_arm_elbow_link.STL" />
      </geometry>
      <material
        name="">
        <color
          rgba="0.792156862745098 0.819607843137255 0.933333333333333 1" />
      </material>
    </visual>
    <collision>
      <origin
        xyz="0 0 0"
        rpy="0 0 0" />
      <geometry>
        <mesh
          filename="package://bearmax_description/meshes/right_arm_elbow_link.STL" />
      </geometry>
    </collision>
  </link>
  <joint
    name="right_arm_elbow_joint"
    type="continuous">
    <origin
      xyz="0.0018031 0.13145 0.0018031"
      rpy="2.1424 0.57212 0.87114" />
    <parent
      link="right_arm_rotator_link" />
    <child
      link="right_arm_elbow_link" />
    <axis
      xyz="0 1 0" />
  </joint>
</robot>
